The following values were not passed to `accelerate launch` and had defaults used instead:
		More than one GPU was found, enabling multi-GPU training.
		If this was unintended please pass in `--num_processes=1`.
	`--mixed_precision` was set to a value of `'no'`
	`--dynamo_backend` was set to a value of `'no'`
To avoid this warning pass in values for each of the problematic parameters or run `accelerate config`.
/opt/hpcaas/.mounts/fs-0301404b74c8d22fd/home/winnieyangwn/deception_and_jailbreak/src/submodules/truthfulQA
current_directory: /opt/hpcaas/.mounts/fs-0301404b74c8d22fd/home/winnieyangwn/deception_and_jailbreak/src/submodules/truthfulQA
/opt/hpcaas/.mounts/fs-0301404b74c8d22fd/home/winnieyangwn/deception_and_jailbreak/src/submodules/truthfulQA
current_directory: /opt/hpcaas/.mounts/fs-0301404b74c8d22fd/home/winnieyangwn/deception_and_jailbreak/src/submodules/truthfulQA
/opt/hpcaas/.mounts/fs-0301404b74c8d22fd/home/winnieyangwn/deception_and_jailbreak/src/submodules/truthfulQA/opt/hpcaas/.mounts/fs-0301404b74c8d22fd/home/winnieyangwn/deception_and_jailbreak/src/submodules/truthfulQA/opt/hpcaas/.mounts/fs-0301404b74c8d22fd/home/winnieyangwn/deception_and_jailbreak/src/submodules/truthfulQA
current_directory: 
current_directory: /opt/hpcaas/.mounts/fs-0301404b74c8d22fd/home/winnieyangwn/deception_and_jailbreak/src/submodules/truthfulQA
/opt/hpcaas/.mounts/fs-0301404b74c8d22fd/home/winnieyangwn/deception_and_jailbreak/src/submodules/truthfulQA
/opt/hpcaas/.mounts/fs-0301404b74c8d22fd/home/winnieyangwn/deception_and_jailbreak/src/submodules/truthfulQA
current_directory: /opt/hpcaas/.mounts/fs-0301404b74c8d22fd/home/winnieyangwn/deception_and_jailbreak/src/submodules/truthfulQA

current_directory: /opt/hpcaas/.mounts/fs-0301404b74c8d22fd/home/winnieyangwn/deception_and_jailbreak/src/submodules/truthfulQA
/opt/hpcaas/.mounts/fs-0301404b74c8d22fd/home/winnieyangwn/deception_and_jailbreak/src/submodules/truthfulQA
current_directory: /opt/hpcaas/.mounts/fs-0301404b74c8d22fd/home/winnieyangwn/deception_and_jailbreak/src/submodules/truthfulQA
/opt/hpcaas/.mounts/fs-0301404b74c8d22fd/home/winnieyangwn/deception_and_jailbreak/src/submodules/truthfulQA
current_directory: /opt/hpcaas/.mounts/fs-0301404b74c8d22fd/home/winnieyangwn/deception_and_jailbreak/src/submodules/truthfulQA
[W327 10:26:18.001363032 Utils.hpp:135] Warning: Environment variable NCCL_ASYNC_ERROR_HANDLING is deprecated; use TORCH_NCCL_ASYNC_ERROR_HANDLING instead (function operator())
[W327 10:26:18.524096528 Utils.hpp:135] Warning: Environment variable NCCL_ASYNC_ERROR_HANDLING is deprecated; use TORCH_NCCL_ASYNC_ERROR_HANDLING instead (function operator())
[W327 10:26:19.116999340 Utils.hpp:135] Warning: Environment variable NCCL_ASYNC_ERROR_HANDLING is deprecated; use TORCH_NCCL_ASYNC_ERROR_HANDLING instead (function operator())
[W327 10:26:19.135267044 Utils.hpp:135] Warning: Environment variable NCCL_ASYNC_ERROR_HANDLING is deprecated; use TORCH_NCCL_ASYNC_ERROR_HANDLING instead (function operator())
[W327 10:26:19.402988819 Utils.hpp:135] Warning: Environment variable NCCL_ASYNC_ERROR_HANDLING is deprecated; use TORCH_NCCL_ASYNC_ERROR_HANDLING instead (function operator())
[W327 10:26:19.544925323 Utils.hpp:135] Warning: Environment variable NCCL_ASYNC_ERROR_HANDLING is deprecated; use TORCH_NCCL_ASYNC_ERROR_HANDLING instead (function operator())
[W327 10:26:19.652470951 Utils.hpp:135] Warning: Environment variable NCCL_ASYNC_ERROR_HANDLING is deprecated; use TORCH_NCCL_ASYNC_ERROR_HANDLING instead (function operator())
[W327 10:26:20.827315654 Utils.hpp:135] Warning: Environment variable NCCL_ASYNC_ERROR_HANDLING is deprecated; use TORCH_NCCL_ASYNC_ERROR_HANDLING instead (function operator())
Using 8 GPUs
Process rank: 0
cfg: Config(model_path='meta-llama/Llama-3.1-70B-Instuct', model_name='Llama-3.1-70B-Instuct', save_dir='/home/winnieyangwn/Output', entity_type='song', n_positions=1, n_train=512, n_test=128, batch_size=128, max_new_tokens=2, task_name='truthful_qa', steer_type='negative_addition', source_layer=14, target_layer=14, contrastive_type=('factual', 'misconception'), steering_strength=1)
Generating train split: 0 examples [00:00, ? examples/s]Generating train split: 790 examples [00:00, 10008.03 examples/s]
Train size: 512
Test size: 128
[rank1]: Traceback (most recent call last):
[rank1]:   File "/home/winnieyangwn/miniconda3/envs/refat/lib/python3.11/site-packages/huggingface_hub/utils/_http.py", line 409, in hf_raise_for_status
[rank1]:     response.raise_for_status()
[rank1]:   File "/home/winnieyangwn/miniconda3/envs/refat/lib/python3.11/site-packages/requests/models.py", line 1024, in raise_for_status
[rank1]:     raise HTTPError(http_error_msg, response=self)
[rank1]: requests.exceptions.HTTPError: 404 Client Error: Not Found for url: https://huggingface.co/meta-llama/Llama-3.1-70B-Instuct/resolve/main/config.json

[rank1]: The above exception was the direct cause of the following exception:

[rank1]: Traceback (most recent call last):
[rank1]:   File "/home/winnieyangwn/miniconda3/envs/refat/lib/python3.11/site-packages/transformers/utils/hub.py", line 342, in cached_file
[rank1]:     resolved_file = hf_hub_download(
[rank1]:                     ^^^^^^^^^^^^^^^^
[rank1]:   File "/home/winnieyangwn/miniconda3/envs/refat/lib/python3.11/site-packages/huggingface_hub/utils/_validators.py", line 114, in _inner_fn
[rank1]:     return fn(*args, **kwargs)
[rank1]:            ^^^^^^^^^^^^^^^^^^^
[rank1]:   File "/home/winnieyangwn/miniconda3/envs/refat/lib/python3.11/site-packages/huggingface_hub/file_download.py", line 862, in hf_hub_download
[rank1]:     return _hf_hub_download_to_cache_dir(
[rank1]:            ^^^^^^^^^^^^^^^^^^^^^^^^^^^^^^
[rank1]:   File "/home/winnieyangwn/miniconda3/envs/refat/lib/python3.11/site-packages/huggingface_hub/file_download.py", line 969, in _hf_hub_download_to_cache_dir
[rank1]:     _raise_on_head_call_error(head_call_error, force_download, local_files_only)
[rank1]:   File "/home/winnieyangwn/miniconda3/envs/refat/lib/python3.11/site-packages/huggingface_hub/file_download.py", line 1486, in _raise_on_head_call_error
[rank1]:     raise head_call_error
[rank1]:   File "/home/winnieyangwn/miniconda3/envs/refat/lib/python3.11/site-packages/huggingface_hub/file_download.py", line 1376, in _get_metadata_or_catch_error
[rank1]:     metadata = get_hf_file_metadata(
[rank1]:                ^^^^^^^^^^^^^^^^^^^^^
[rank1]:   File "/home/winnieyangwn/miniconda3/envs/refat/lib/python3.11/site-packages/huggingface_hub/utils/_validators.py", line 114, in _inner_fn
[rank1]:     return fn(*args, **kwargs)
[rank1]:            ^^^^^^^^^^^^^^^^^^^
[rank1]:   File "/home/winnieyangwn/miniconda3/envs/refat/lib/python3.11/site-packages/huggingface_hub/file_download.py", line 1296, in get_hf_file_metadata
[rank1]:     r = _request_wrapper(
[rank1]:         ^^^^^^^^^^^^^^^^^
[rank1]:   File "/home/winnieyangwn/miniconda3/envs/refat/lib/python3.11/site-packages/huggingface_hub/file_download.py", line 280, in _request_wrapper
[rank1]:     response = _request_wrapper(
[rank1]:                ^^^^^^^^^^^^^^^^^
[rank1]:   File "/home/winnieyangwn/miniconda3/envs/refat/lib/python3.11/site-packages/huggingface_hub/file_download.py", line 304, in _request_wrapper
[rank1]:     hf_raise_for_status(response)
[rank1]:   File "/home/winnieyangwn/miniconda3/envs/refat/lib/python3.11/site-packages/huggingface_hub/utils/_http.py", line 458, in hf_raise_for_status
[rank1]:     raise _format(RepositoryNotFoundError, message, response) from e
[rank1]: huggingface_hub.errors.RepositoryNotFoundError: 404 Client Error. (Request ID: Root=1-67e527cf-4c809dc94843d9db48a8e9d4;ce60dd0f-9562-4554-91ab-f7a50abf81b7)

[rank1]: Repository Not Found for url: https://huggingface.co/meta-llama/Llama-3.1-70B-Instuct/resolve/main/config.json.
[rank1]: Please make sure you specified the correct `repo_id` and `repo_type`.
[rank1]: If you are trying to access a private or gated repo, make sure you are authenticated.

[rank1]: The above exception was the direct cause of the following exception:

[rank1]: Traceback (most recent call last):
[rank1]:   File "/opt/hpcaas/.mounts/fs-0301404b74c8d22fd/home/winnieyangwn/deception_and_jailbreak/src/submodules/truthfulQA/run_truthfulqa.py", line 122, in <module>
[rank1]:     main(model_path=args.model_path, 
[rank1]:     ^^^^^^^^^^^^^^^^^^^^^^^^^^^^^^^^
[rank1]:   File "/opt/hpcaas/.mounts/fs-0301404b74c8d22fd/home/winnieyangwn/deception_and_jailbreak/src/submodules/truthfulQA/run_truthfulqa.py", line 113, in main
[rank1]:     model_base = TransformerModelLoader(model_path, accelerator=accelerator)
[rank1]:                  ^^^^^^^^^^^^^^^^^^^^^^^^^^^^^^^^^^^^^^^^^^^^^^^^^^^^^^^^^^^
[rank1]:   File "/opt/hpcaas/.mounts/fs-0301404b74c8d22fd/home/winnieyangwn/deception_and_jailbreak/src/submodules/truthfulQA/model_base.py", line 41, in __init__
[rank1]:     self.model = AutoModelForCausalLM.from_pretrained(
[rank1]:                  ^^^^^^^^^^^^^^^^^^^^^^^^^^^^^^^^^^^^^
[rank1]:   File "/home/winnieyangwn/miniconda3/envs/refat/lib/python3.11/site-packages/transformers/models/auto/auto_factory.py", line 487, in from_pretrained
[rank1]:     resolved_config_file = cached_file(
[rank1]:                            ^^^^^^^^^^^^
[rank1]:   File "/home/winnieyangwn/miniconda3/envs/refat/lib/python3.11/site-packages/transformers/utils/hub.py", line 365, in cached_file
[rank1]:     raise EnvironmentError(
[rank1]: OSError: meta-llama/Llama-3.1-70B-Instuct is not a local folder and is not a valid model identifier listed on 'https://huggingface.co/models'
[rank1]: If this is a private repository, make sure to pass a token having permission to this repo either by logging in with `huggingface-cli login` or by passing `token=<your_token>`
[rank7]: Traceback (most recent call last):
[rank7]:   File "/home/winnieyangwn/miniconda3/envs/refat/lib/python3.11/site-packages/huggingface_hub/utils/_http.py", line 409, in hf_raise_for_status
[rank7]:     response.raise_for_status()
[rank7]:   File "/home/winnieyangwn/miniconda3/envs/refat/lib/python3.11/site-packages/requests/models.py", line 1024, in raise_for_status
[rank7]:     raise HTTPError(http_error_msg, response=self)
[rank7]: requests.exceptions.HTTPError: 404 Client Error: Not Found for url: https://huggingface.co/meta-llama/Llama-3.1-70B-Instuct/resolve/main/config.json

[rank7]: The above exception was the direct cause of the following exception:

[rank7]: Traceback (most recent call last):
[rank7]:   File "/home/winnieyangwn/miniconda3/envs/refat/lib/python3.11/site-packages/transformers/utils/hub.py", line 342, in cached_file
[rank7]:     resolved_file = hf_hub_download(
[rank7]:                     ^^^^^^^^^^^^^^^^
[rank7]:   File "/home/winnieyangwn/miniconda3/envs/refat/lib/python3.11/site-packages/huggingface_hub/utils/_validators.py", line 114, in _inner_fn
[rank7]:     return fn(*args, **kwargs)
[rank7]:            ^^^^^^^^^^^^^^^^^^^
[rank7]:   File "/home/winnieyangwn/miniconda3/envs/refat/lib/python3.11/site-packages/huggingface_hub/file_download.py", line 862, in hf_hub_download
[rank7]:     return _hf_hub_download_to_cache_dir(
[rank7]:            ^^^^^^^^^^^^^^^^^^^^^^^^^^^^^^
[rank7]:   File "/home/winnieyangwn/miniconda3/envs/refat/lib/python3.11/site-packages/huggingface_hub/file_download.py", line 969, in _hf_hub_download_to_cache_dir
[rank7]:     _raise_on_head_call_error(head_call_error, force_download, local_files_only)
[rank7]:   File "/home/winnieyangwn/miniconda3/envs/refat/lib/python3.11/site-packages/huggingface_hub/file_download.py", line 1486, in _raise_on_head_call_error
[rank7]:     raise head_call_error
[rank7]:   File "/home/winnieyangwn/miniconda3/envs/refat/lib/python3.11/site-packages/huggingface_hub/file_download.py", line 1376, in _get_metadata_or_catch_error
[rank7]:     metadata = get_hf_file_metadata(
[rank7]:                ^^^^^^^^^^^^^^^^^^^^^
[rank7]:   File "/home/winnieyangwn/miniconda3/envs/refat/lib/python3.11/site-packages/huggingface_hub/utils/_validators.py", line 114, in _inner_fn
[rank7]:     return fn(*args, **kwargs)
[rank7]:            ^^^^^^^^^^^^^^^^^^^
[rank7]:   File "/home/winnieyangwn/miniconda3/envs/refat/lib/python3.11/site-packages/huggingface_hub/file_download.py", line 1296, in get_hf_file_metadata
[rank7]:     r = _request_wrapper(
[rank7]:         ^^^^^^^^^^^^^^^^^
[rank7]:   File "/home/winnieyangwn/miniconda3/envs/refat/lib/python3.11/site-packages/huggingface_hub/file_download.py", line 280, in _request_wrapper
[rank7]:     response = _request_wrapper(
[rank7]:                ^^^^^^^^^^^^^^^^^
[rank7]:   File "/home/winnieyangwn/miniconda3/envs/refat/lib/python3.11/site-packages/huggingface_hub/file_download.py", line 304, in _request_wrapper
[rank7]:     hf_raise_for_status(response)
[rank7]:   File "/home/winnieyangwn/miniconda3/envs/refat/lib/python3.11/site-packages/huggingface_hub/utils/_http.py", line 458, in hf_raise_for_status
[rank7]:     raise _format(RepositoryNotFoundError, message, response) from e
[rank7]: huggingface_hub.errors.RepositoryNotFoundError: 404 Client Error. (Request ID: Root=1-67e527cf-198123a6529c36174af78987;08299bd4-ee36-420b-9dd8-b29ca7e7367f)

[rank7]: Repository Not Found for url: https://huggingface.co/meta-llama/Llama-3.1-70B-Instuct/resolve/main/config.json.
[rank7]: Please make sure you specified the correct `repo_id` and `repo_type`.
[rank7]: If you are trying to access a private or gated repo, make sure you are authenticated.

[rank7]: The above exception was the direct cause of the following exception:

[rank7]: Traceback (most recent call last):
[rank7]:   File "/opt/hpcaas/.mounts/fs-0301404b74c8d22fd/home/winnieyangwn/deception_and_jailbreak/src/submodules/truthfulQA/run_truthfulqa.py", line 122, in <module>
[rank7]:     main(model_path=args.model_path, 
[rank7]:     ^^^^^^^^^^^^^^^^^^^^^^^^^^^^^^^^
[rank7]:   File "/opt/hpcaas/.mounts/fs-0301404b74c8d22fd/home/winnieyangwn/deception_and_jailbreak/src/submodules/truthfulQA/run_truthfulqa.py", line 113, in main
[rank7]:     model_base = TransformerModelLoader(model_path, accelerator=accelerator)
[rank7]:                  ^^^^^^^^^^^^^^^^^^^^^^^^^^^^^^^^^^^^^^^^^^^^^^^^^^^^^^^^^^^
[rank7]:   File "/opt/hpcaas/.mounts/fs-0301404b74c8d22fd/home/winnieyangwn/deception_and_jailbreak/src/submodules/truthfulQA/model_base.py", line 41, in __init__
[rank7]:     self.model = AutoModelForCausalLM.from_pretrained(
[rank7]:                  ^^^^^^^^^^^^^^^^^^^^^^^^^^^^^^^^^^^^^
[rank7]:   File "/home/winnieyangwn/miniconda3/envs/refat/lib/python3.11/site-packages/transformers/models/auto/auto_factory.py", line 487, in from_pretrained
[rank7]:     resolved_config_file = cached_file(
[rank7]:                            ^^^^^^^^^^^^
[rank7]:   File "/home/winnieyangwn/miniconda3/envs/refat/lib/python3.11/site-packages/transformers/utils/hub.py", line 365, in cached_file
[rank7]:     raise EnvironmentError(
[rank7]: OSError: meta-llama/Llama-3.1-70B-Instuct is not a local folder and is not a valid model identifier listed on 'https://huggingface.co/models'
[rank7]: If this is a private repository, make sure to pass a token having permission to this repo either by logging in with `huggingface-cli login` or by passing `token=<your_token>`
[rank3]: Traceback (most recent call last):
[rank3]:   File "/home/winnieyangwn/miniconda3/envs/refat/lib/python3.11/site-packages/huggingface_hub/utils/_http.py", line 409, in hf_raise_for_status
[rank3]:     response.raise_for_status()
[rank3]:   File "/home/winnieyangwn/miniconda3/envs/refat/lib/python3.11/site-packages/requests/models.py", line 1024, in raise_for_status
[rank3]:     raise HTTPError(http_error_msg, response=self)
[rank3]: requests.exceptions.HTTPError: 404 Client Error: Not Found for url: https://huggingface.co/meta-llama/Llama-3.1-70B-Instuct/resolve/main/config.json

[rank3]: The above exception was the direct cause of the following exception:

[rank3]: Traceback (most recent call last):
[rank3]:   File "/home/winnieyangwn/miniconda3/envs/refat/lib/python3.11/site-packages/transformers/utils/hub.py", line 342, in cached_file
[rank3]:     resolved_file = hf_hub_download(
[rank3]:                     ^^^^^^^^^^^^^^^^
[rank3]:   File "/home/winnieyangwn/miniconda3/envs/refat/lib/python3.11/site-packages/huggingface_hub/utils/_validators.py", line 114, in _inner_fn
[rank3]:     return fn(*args, **kwargs)
[rank3]:            ^^^^^^^^^^^^^^^^^^^
[rank3]:   File "/home/winnieyangwn/miniconda3/envs/refat/lib/python3.11/site-packages/huggingface_hub/file_download.py", line 862, in hf_hub_download
[rank3]:     return _hf_hub_download_to_cache_dir(
[rank3]:            ^^^^^^^^^^^^^^^^^^^^^^^^^^^^^^
[rank3]:   File "/home/winnieyangwn/miniconda3/envs/refat/lib/python3.11/site-packages/huggingface_hub/file_download.py", line 969, in _hf_hub_download_to_cache_dir
[rank3]:     _raise_on_head_call_error(head_call_error, force_download, local_files_only)
[rank3]:   File "/home/winnieyangwn/miniconda3/envs/refat/lib/python3.11/site-packages/huggingface_hub/file_download.py", line 1486, in _raise_on_head_call_error
[rank3]:     raise head_call_error
[rank3]:   File "/home/winnieyangwn/miniconda3/envs/refat/lib/python3.11/site-packages/huggingface_hub/file_download.py", line 1376, in _get_metadata_or_catch_error
[rank3]:     metadata = get_hf_file_metadata(
[rank3]:                ^^^^^^^^^^^^^^^^^^^^^
[rank3]:   File "/home/winnieyangwn/miniconda3/envs/refat/lib/python3.11/site-packages/huggingface_hub/utils/_validators.py", line 114, in _inner_fn
[rank3]:     return fn(*args, **kwargs)
[rank3]:            ^^^^^^^^^^^^^^^^^^^
[rank3]:   File "/home/winnieyangwn/miniconda3/envs/refat/lib/python3.11/site-packages/huggingface_hub/file_download.py", line 1296, in get_hf_file_metadata
[rank3]:     r = _request_wrapper(
[rank3]:         ^^^^^^^^^^^^^^^^^
[rank3]:   File "/home/winnieyangwn/miniconda3/envs/refat/lib/python3.11/site-packages/huggingface_hub/file_download.py", line 280, in _request_wrapper
[rank3]:     response = _request_wrapper(
[rank3]:                ^^^^^^^^^^^^^^^^^
[rank3]:   File "/home/winnieyangwn/miniconda3/envs/refat/lib/python3.11/site-packages/huggingface_hub/file_download.py", line 304, in _request_wrapper
[rank3]:     hf_raise_for_status(response)
[rank3]:   File "/home/winnieyangwn/miniconda3/envs/refat/lib/python3.11/site-packages/huggingface_hub/utils/_http.py", line 458, in hf_raise_for_status
[rank3]:     raise _format(RepositoryNotFoundError, message, response) from e
[rank3]: huggingface_hub.errors.RepositoryNotFoundError: 404 Client Error. (Request ID: Root=1-67e527cf-40273298733a9eb7307ef5a7;88d117a3-94a6-45a0-bf01-dbbf6389f269)

[rank3]: Repository Not Found for url: https://huggingface.co/meta-llama/Llama-3.1-70B-Instuct/resolve/main/config.json.
[rank3]: Please make sure you specified the correct `repo_id` and `repo_type`.
[rank3]: If you are trying to access a private or gated repo, make sure you are authenticated.

[rank3]: The above exception was the direct cause of the following exception:

[rank3]: Traceback (most recent call last):
[rank3]:   File "/opt/hpcaas/.mounts/fs-0301404b74c8d22fd/home/winnieyangwn/deception_and_jailbreak/src/submodules/truthfulQA/run_truthfulqa.py", line 122, in <module>
[rank3]:     main(model_path=args.model_path, 
[rank3]:     ^^^^^^^^^^^^^^^^^^^^^^^^^^^^^^^^
[rank3]:   File "/opt/hpcaas/.mounts/fs-0301404b74c8d22fd/home/winnieyangwn/deception_and_jailbreak/src/submodules/truthfulQA/run_truthfulqa.py", line 113, in main
[rank3]:     model_base = TransformerModelLoader(model_path, accelerator=accelerator)
[rank3]:                  ^^^^^^^^^^^^^^^^^^^^^^^^^^^^^^^^^^^^^^^^^^^^^^^^^^^^^^^^^^^
[rank3]:   File "/opt/hpcaas/.mounts/fs-0301404b74c8d22fd/home/winnieyangwn/deception_and_jailbreak/src/submodules/truthfulQA/model_base.py", line 41, in __init__
[rank3]:     self.model = AutoModelForCausalLM.from_pretrained(
[rank3]:                  ^^^^^^^^^^^^^^^^^^^^^^^^^^^^^^^^^^^^^
[rank3]:   File "/home/winnieyangwn/miniconda3/envs/refat/lib/python3.11/site-packages/transformers/models/auto/auto_factory.py", line 487, in from_pretrained
[rank3]:     resolved_config_file = cached_file(
[rank3]:                            ^^^^^^^^^^^^
[rank3]:   File "/home/winnieyangwn/miniconda3/envs/refat/lib/python3.11/site-packages/transformers/utils/hub.py", line 365, in cached_file
[rank3]:     raise EnvironmentError(
[rank3]: OSError: meta-llama/Llama-3.1-70B-Instuct is not a local folder and is not a valid model identifier listed on 'https://huggingface.co/models'
[rank3]: If this is a private repository, make sure to pass a token having permission to this repo either by logging in with `huggingface-cli login` or by passing `token=<your_token>`
[rank6]: Traceback (most recent call last):
[rank6]:   File "/home/winnieyangwn/miniconda3/envs/refat/lib/python3.11/site-packages/huggingface_hub/utils/_http.py", line 409, in hf_raise_for_status
[rank6]:     response.raise_for_status()
[rank6]:   File "/home/winnieyangwn/miniconda3/envs/refat/lib/python3.11/site-packages/requests/models.py", line 1024, in raise_for_status
[rank6]:     raise HTTPError(http_error_msg, response=self)
[rank6]: requests.exceptions.HTTPError: 404 Client Error: Not Found for url: https://huggingface.co/meta-llama/Llama-3.1-70B-Instuct/resolve/main/config.json

[rank6]: The above exception was the direct cause of the following exception:

[rank6]: Traceback (most recent call last):
[rank6]:   File "/home/winnieyangwn/miniconda3/envs/refat/lib/python3.11/site-packages/transformers/utils/hub.py", line 342, in cached_file
[rank6]:     resolved_file = hf_hub_download(
[rank6]:                     ^^^^^^^^^^^^^^^^
[rank6]:   File "/home/winnieyangwn/miniconda3/envs/refat/lib/python3.11/site-packages/huggingface_hub/utils/_validators.py", line 114, in _inner_fn
[rank6]:     return fn(*args, **kwargs)
[rank6]:            ^^^^^^^^^^^^^^^^^^^
[rank6]:   File "/home/winnieyangwn/miniconda3/envs/refat/lib/python3.11/site-packages/huggingface_hub/file_download.py", line 862, in hf_hub_download
[rank6]:     return _hf_hub_download_to_cache_dir(
[rank6]:            ^^^^^^^^^^^^^^^^^^^^^^^^^^^^^^
[rank6]:   File "/home/winnieyangwn/miniconda3/envs/refat/lib/python3.11/site-packages/huggingface_hub/file_download.py", line 969, in _hf_hub_download_to_cache_dir
[rank6]:     _raise_on_head_call_error(head_call_error, force_download, local_files_only)
[rank6]:   File "/home/winnieyangwn/miniconda3/envs/refat/lib/python3.11/site-packages/huggingface_hub/file_download.py", line 1486, in _raise_on_head_call_error
[rank6]:     raise head_call_error
[rank6]:   File "/home/winnieyangwn/miniconda3/envs/refat/lib/python3.11/site-packages/huggingface_hub/file_download.py", line 1376, in _get_metadata_or_catch_error
[rank6]:     metadata = get_hf_file_metadata(
[rank6]:                ^^^^^^^^^^^^^^^^^^^^^
[rank6]:   File "/home/winnieyangwn/miniconda3/envs/refat/lib/python3.11/site-packages/huggingface_hub/utils/_validators.py", line 114, in _inner_fn
[rank6]:     return fn(*args, **kwargs)
[rank6]:            ^^^^^^^^^^^^^^^^^^^
[rank6]:   File "/home/winnieyangwn/miniconda3/envs/refat/lib/python3.11/site-packages/huggingface_hub/file_download.py", line 1296, in get_hf_file_metadata
[rank6]:     r = _request_wrapper(
[rank6]:         ^^^^^^^^^^^^^^^^^
[rank6]:   File "/home/winnieyangwn/miniconda3/envs/refat/lib/python3.11/site-packages/huggingface_hub/file_download.py", line 280, in _request_wrapper
[rank6]:     response = _request_wrapper(
[rank6]:                ^^^^^^^^^^^^^^^^^
[rank6]:   File "/home/winnieyangwn/miniconda3/envs/refat/lib/python3.11/site-packages/huggingface_hub/file_download.py", line 304, in _request_wrapper
[rank6]:     hf_raise_for_status(response)
[rank6]:   File "/home/winnieyangwn/miniconda3/envs/refat/lib/python3.11/site-packages/huggingface_hub/utils/_http.py", line 458, in hf_raise_for_status
[rank6]:     raise _format(RepositoryNotFoundError, message, response) from e
[rank6]: huggingface_hub.errors.RepositoryNotFoundError: 404 Client Error. (Request ID: Root=1-67e527cf-783ef1ac37dcc5a07278e5a6;3089e278-1c7b-4691-86d8-b227b753f1cd)

[rank6]: Repository Not Found for url: https://huggingface.co/meta-llama/Llama-3.1-70B-Instuct/resolve/main/config.json.
[rank6]: Please make sure you specified the correct `repo_id` and `repo_type`.
[rank6]: If you are trying to access a private or gated repo, make sure you are authenticated.

[rank6]: The above exception was the direct cause of the following exception:

[rank6]: Traceback (most recent call last):
[rank6]:   File "/opt/hpcaas/.mounts/fs-0301404b74c8d22fd/home/winnieyangwn/deception_and_jailbreak/src/submodules/truthfulQA/run_truthfulqa.py", line 122, in <module>
[rank6]:     main(model_path=args.model_path, 
[rank6]:     ^^^^^^^^^^^^^^^^^^^^^^^^^^^^^^^^
[rank6]:   File "/opt/hpcaas/.mounts/fs-0301404b74c8d22fd/home/winnieyangwn/deception_and_jailbreak/src/submodules/truthfulQA/run_truthfulqa.py", line 113, in main
[rank6]:     model_base = TransformerModelLoader(model_path, accelerator=accelerator)
[rank6]:                  ^^^^^^^^^^^^^^^^^^^^^^^^^^^^^^^^^^^^^^^^^^^^^^^^^^^^^^^^^^^
[rank6]:   File "/opt/hpcaas/.mounts/fs-0301404b74c8d22fd/home/winnieyangwn/deception_and_jailbreak/src/submodules/truthfulQA/model_base.py", line 41, in __init__
[rank6]:     self.model = AutoModelForCausalLM.from_pretrained(
[rank6]:                  ^^^^^^^^^^^^^^^^^^^^^^^^^^^^^^^^^^^^^
[rank6]:   File "/home/winnieyangwn/miniconda3/envs/refat/lib/python3.11/site-packages/transformers/models/auto/auto_factory.py", line 487, in from_pretrained
[rank6]:     resolved_config_file = cached_file(
[rank6]:                            ^^^^^^^^^^^^
[rank6]:   File "/home/winnieyangwn/miniconda3/envs/refat/lib/python3.11/site-packages/transformers/utils/hub.py", line 365, in cached_file
[rank6]:     raise EnvironmentError(
[rank6]: OSError: meta-llama/Llama-3.1-70B-Instuct is not a local folder and is not a valid model identifier listed on 'https://huggingface.co/models'
[rank6]: If this is a private repository, make sure to pass a token having permission to this repo either by logging in with `huggingface-cli login` or by passing `token=<your_token>`
[rank4]: Traceback (most recent call last):
[rank4]:   File "/home/winnieyangwn/miniconda3/envs/refat/lib/python3.11/site-packages/huggingface_hub/utils/_http.py", line 409, in hf_raise_for_status
[rank4]:     response.raise_for_status()
[rank4]:   File "/home/winnieyangwn/miniconda3/envs/refat/lib/python3.11/site-packages/requests/models.py", line 1024, in raise_for_status
[rank4]:     raise HTTPError(http_error_msg, response=self)
[rank4]: requests.exceptions.HTTPError: 404 Client Error: Not Found for url: https://huggingface.co/meta-llama/Llama-3.1-70B-Instuct/resolve/main/config.json

[rank4]: The above exception was the direct cause of the following exception:

[rank4]: Traceback (most recent call last):
[rank4]:   File "/home/winnieyangwn/miniconda3/envs/refat/lib/python3.11/site-packages/transformers/utils/hub.py", line 342, in cached_file
[rank4]:     resolved_file = hf_hub_download(
[rank4]:                     ^^^^^^^^^^^^^^^^
[rank4]:   File "/home/winnieyangwn/miniconda3/envs/refat/lib/python3.11/site-packages/huggingface_hub/utils/_validators.py", line 114, in _inner_fn
[rank4]:     return fn(*args, **kwargs)
[rank4]:            ^^^^^^^^^^^^^^^^^^^
[rank4]:   File "/home/winnieyangwn/miniconda3/envs/refat/lib/python3.11/site-packages/huggingface_hub/file_download.py", line 862, in hf_hub_download
[rank4]:     return _hf_hub_download_to_cache_dir(
[rank4]:            ^^^^^^^^^^^^^^^^^^^^^^^^^^^^^^
[rank4]:   File "/home/winnieyangwn/miniconda3/envs/refat/lib/python3.11/site-packages/huggingface_hub/file_download.py", line 969, in _hf_hub_download_to_cache_dir
[rank4]:     _raise_on_head_call_error(head_call_error, force_download, local_files_only)
[rank4]:   File "/home/winnieyangwn/miniconda3/envs/refat/lib/python3.11/site-packages/huggingface_hub/file_download.py", line 1486, in _raise_on_head_call_error
[rank4]:     raise head_call_error
[rank4]:   File "/home/winnieyangwn/miniconda3/envs/refat/lib/python3.11/site-packages/huggingface_hub/file_download.py", line 1376, in _get_metadata_or_catch_error
[rank4]:     metadata = get_hf_file_metadata(
[rank4]:                ^^^^^^^^^^^^^^^^^^^^^
[rank4]:   File "/home/winnieyangwn/miniconda3/envs/refat/lib/python3.11/site-packages/huggingface_hub/utils/_validators.py", line 114, in _inner_fn
[rank4]:     return fn(*args, **kwargs)
[rank4]:            ^^^^^^^^^^^^^^^^^^^
[rank4]:   File "/home/winnieyangwn/miniconda3/envs/refat/lib/python3.11/site-packages/huggingface_hub/file_download.py", line 1296, in get_hf_file_metadata
[rank4]:     r = _request_wrapper(
[rank4]:         ^^^^^^^^^^^^^^^^^
[rank4]:   File "/home/winnieyangwn/miniconda3/envs/refat/lib/python3.11/site-packages/huggingface_hub/file_download.py", line 280, in _request_wrapper
[rank4]:     response = _request_wrapper(
[rank4]:                ^^^^^^^^^^^^^^^^^
[rank4]:   File "/home/winnieyangwn/miniconda3/envs/refat/lib/python3.11/site-packages/huggingface_hub/file_download.py", line 304, in _request_wrapper
[rank4]:     hf_raise_for_status(response)
[rank4]:   File "/home/winnieyangwn/miniconda3/envs/refat/lib/python3.11/site-packages/huggingface_hub/utils/_http.py", line 458, in hf_raise_for_status
[rank4]:     raise _format(RepositoryNotFoundError, message, response) from e
[rank4]: huggingface_hub.errors.RepositoryNotFoundError: 404 Client Error. (Request ID: Root=1-67e527cf-3353cf8a02ffc0d649c8a25b;800b91fb-cdd2-4733-9fbb-d7f1c25c906e)

[rank4]: Repository Not Found for url: https://huggingface.co/meta-llama/Llama-3.1-70B-Instuct/resolve/main/config.json.
[rank4]: Please make sure you specified the correct `repo_id` and `repo_type`.
[rank4]: If you are trying to access a private or gated repo, make sure you are authenticated.

[rank4]: The above exception was the direct cause of the following exception:

[rank4]: Traceback (most recent call last):
[rank4]:   File "/opt/hpcaas/.mounts/fs-0301404b74c8d22fd/home/winnieyangwn/deception_and_jailbreak/src/submodules/truthfulQA/run_truthfulqa.py", line 122, in <module>
[rank4]:     main(model_path=args.model_path, 
[rank4]:     ^^^^^^^^^^^^^^^^^^^^^^^^^^^^^^^^
[rank4]:   File "/opt/hpcaas/.mounts/fs-0301404b74c8d22fd/home/winnieyangwn/deception_and_jailbreak/src/submodules/truthfulQA/run_truthfulqa.py", line 113, in main
[rank4]:     model_base = TransformerModelLoader(model_path, accelerator=accelerator)
[rank4]:                  ^^^^^^^^^^^^^^^^^^^^^^^^^^^^^^^^^^^^^^^^^^^^^^^^^^^^^^^^^^^
[rank4]:   File "/opt/hpcaas/.mounts/fs-0301404b74c8d22fd/home/winnieyangwn/deception_and_jailbreak/src/submodules/truthfulQA/model_base.py", line 41, in __init__
[rank4]:     self.model = AutoModelForCausalLM.from_pretrained(
[rank4]:                  ^^^^^^^^^^^^^^^^^^^^^^^^^^^^^^^^^^^^^
[rank4]:   File "/home/winnieyangwn/miniconda3/envs/refat/lib/python3.11/site-packages/transformers/models/auto/auto_factory.py", line 487, in from_pretrained
[rank4]:     resolved_config_file = cached_file(
[rank4]:                            ^^^^^^^^^^^^
[rank4]:   File "/home/winnieyangwn/miniconda3/envs/refat/lib/python3.11/site-packages/transformers/utils/hub.py", line 365, in cached_file
[rank4]:     raise EnvironmentError(
[rank4]: OSError: meta-llama/Llama-3.1-70B-Instuct is not a local folder and is not a valid model identifier listed on 'https://huggingface.co/models'
[rank4]: If this is a private repository, make sure to pass a token having permission to this repo either by logging in with `huggingface-cli login` or by passing `token=<your_token>`
[rank5]: Traceback (most recent call last):
[rank5]:   File "/home/winnieyangwn/miniconda3/envs/refat/lib/python3.11/site-packages/huggingface_hub/utils/_http.py", line 409, in hf_raise_for_status
[rank5]:     response.raise_for_status()
[rank5]:   File "/home/winnieyangwn/miniconda3/envs/refat/lib/python3.11/site-packages/requests/models.py", line 1024, in raise_for_status
[rank5]:     raise HTTPError(http_error_msg, response=self)
[rank5]: requests.exceptions.HTTPError: 404 Client Error: Not Found for url: https://huggingface.co/meta-llama/Llama-3.1-70B-Instuct/resolve/main/config.json

[rank5]: The above exception was the direct cause of the following exception:

[rank5]: Traceback (most recent call last):
[rank5]:   File "/home/winnieyangwn/miniconda3/envs/refat/lib/python3.11/site-packages/transformers/utils/hub.py", line 342, in cached_file
[rank5]:     resolved_file = hf_hub_download(
[rank5]:                     ^^^^^^^^^^^^^^^^
[rank5]:   File "/home/winnieyangwn/miniconda3/envs/refat/lib/python3.11/site-packages/huggingface_hub/utils/_validators.py", line 114, in _inner_fn
[rank5]:     return fn(*args, **kwargs)
[rank5]:            ^^^^^^^^^^^^^^^^^^^
[rank5]:   File "/home/winnieyangwn/miniconda3/envs/refat/lib/python3.11/site-packages/huggingface_hub/file_download.py", line 862, in hf_hub_download
[rank5]:     return _hf_hub_download_to_cache_dir(
[rank5]:            ^^^^^^^^^^^^^^^^^^^^^^^^^^^^^^
[rank5]:   File "/home/winnieyangwn/miniconda3/envs/refat/lib/python3.11/site-packages/huggingface_hub/file_download.py", line 969, in _hf_hub_download_to_cache_dir
[rank5]:     _raise_on_head_call_error(head_call_error, force_download, local_files_only)
[rank5]:   File "/home/winnieyangwn/miniconda3/envs/refat/lib/python3.11/site-packages/huggingface_hub/file_download.py", line 1486, in _raise_on_head_call_error
[rank5]:     raise head_call_error
[rank5]:   File "/home/winnieyangwn/miniconda3/envs/refat/lib/python3.11/site-packages/huggingface_hub/file_download.py", line 1376, in _get_metadata_or_catch_error
[rank5]:     metadata = get_hf_file_metadata(
[rank5]:                ^^^^^^^^^^^^^^^^^^^^^
[rank5]:   File "/home/winnieyangwn/miniconda3/envs/refat/lib/python3.11/site-packages/huggingface_hub/utils/_validators.py", line 114, in _inner_fn
[rank5]:     return fn(*args, **kwargs)
[rank5]:            ^^^^^^^^^^^^^^^^^^^
[rank5]:   File "/home/winnieyangwn/miniconda3/envs/refat/lib/python3.11/site-packages/huggingface_hub/file_download.py", line 1296, in get_hf_file_metadata
[rank5]:     r = _request_wrapper(
[rank5]:         ^^^^^^^^^^^^^^^^^
[rank5]:   File "/home/winnieyangwn/miniconda3/envs/refat/lib/python3.11/site-packages/huggingface_hub/file_download.py", line 280, in _request_wrapper
[rank5]:     response = _request_wrapper(
[rank5]:                ^^^^^^^^^^^^^^^^^
[rank5]:   File "/home/winnieyangwn/miniconda3/envs/refat/lib/python3.11/site-packages/huggingface_hub/file_download.py", line 304, in _request_wrapper
[rank5]:     hf_raise_for_status(response)
[rank5]:   File "/home/winnieyangwn/miniconda3/envs/refat/lib/python3.11/site-packages/huggingface_hub/utils/_http.py", line 458, in hf_raise_for_status
[rank5]:     raise _format(RepositoryNotFoundError, message, response) from e
[rank5]: huggingface_hub.errors.RepositoryNotFoundError: 404 Client Error. (Request ID: Root=1-67e527cf-367edfb20910d33c7d298537;7a7dbd4e-9873-4213-81e1-1c656b3bb46d)

[rank5]: Repository Not Found for url: https://huggingface.co/meta-llama/Llama-3.1-70B-Instuct/resolve/main/config.json.
[rank5]: Please make sure you specified the correct `repo_id` and `repo_type`.
[rank5]: If you are trying to access a private or gated repo, make sure you are authenticated.

[rank5]: The above exception was the direct cause of the following exception:

[rank5]: Traceback (most recent call last):
[rank5]:   File "/opt/hpcaas/.mounts/fs-0301404b74c8d22fd/home/winnieyangwn/deception_and_jailbreak/src/submodules/truthfulQA/run_truthfulqa.py", line 122, in <module>
[rank5]:     main(model_path=args.model_path, 
[rank5]:     ^^^^^^^^^^^^^^^^^^^^^^^^^^^^^^^^
[rank5]:   File "/opt/hpcaas/.mounts/fs-0301404b74c8d22fd/home/winnieyangwn/deception_and_jailbreak/src/submodules/truthfulQA/run_truthfulqa.py", line 113, in main
[rank5]:     model_base = TransformerModelLoader(model_path, accelerator=accelerator)
[rank5]:                  ^^^^^^^^^^^^^^^^^^^^^^^^^^^^^^^^^^^^^^^^^^^^^^^^^^^^^^^^^^^
[rank5]:   File "/opt/hpcaas/.mounts/fs-0301404b74c8d22fd/home/winnieyangwn/deception_and_jailbreak/src/submodules/truthfulQA/model_base.py", line 41, in __init__
[rank5]:     self.model = AutoModelForCausalLM.from_pretrained(
[rank5]:                  ^^^^^^^^^^^^^^^^^^^^^^^^^^^^^^^^^^^^^
[rank5]:   File "/home/winnieyangwn/miniconda3/envs/refat/lib/python3.11/site-packages/transformers/models/auto/auto_factory.py", line 487, in from_pretrained
[rank5]:     resolved_config_file = cached_file(
[rank5]:                            ^^^^^^^^^^^^
[rank5]:   File "/home/winnieyangwn/miniconda3/envs/refat/lib/python3.11/site-packages/transformers/utils/hub.py", line 365, in cached_file
[rank5]:     raise EnvironmentError(
[rank5]: OSError: meta-llama/Llama-3.1-70B-Instuct is not a local folder and is not a valid model identifier listed on 'https://huggingface.co/models'
[rank5]: If this is a private repository, make sure to pass a token having permission to this repo either by logging in with `huggingface-cli login` or by passing `token=<your_token>`
[rank2]: Traceback (most recent call last):
[rank2]:   File "/home/winnieyangwn/miniconda3/envs/refat/lib/python3.11/site-packages/huggingface_hub/utils/_http.py", line 409, in hf_raise_for_status
[rank2]:     response.raise_for_status()
[rank2]:   File "/home/winnieyangwn/miniconda3/envs/refat/lib/python3.11/site-packages/requests/models.py", line 1024, in raise_for_status
[rank2]:     raise HTTPError(http_error_msg, response=self)
[rank2]: requests.exceptions.HTTPError: 404 Client Error: Not Found for url: https://huggingface.co/meta-llama/Llama-3.1-70B-Instuct/resolve/main/config.json

[rank2]: The above exception was the direct cause of the following exception:

[rank2]: Traceback (most recent call last):
[rank2]:   File "/home/winnieyangwn/miniconda3/envs/refat/lib/python3.11/site-packages/transformers/utils/hub.py", line 342, in cached_file
[rank2]:     resolved_file = hf_hub_download(
[rank2]:                     ^^^^^^^^^^^^^^^^
[rank2]:   File "/home/winnieyangwn/miniconda3/envs/refat/lib/python3.11/site-packages/huggingface_hub/utils/_validators.py", line 114, in _inner_fn
[rank2]:     return fn(*args, **kwargs)
[rank2]:            ^^^^^^^^^^^^^^^^^^^
[rank2]:   File "/home/winnieyangwn/miniconda3/envs/refat/lib/python3.11/site-packages/huggingface_hub/file_download.py", line 862, in hf_hub_download
[rank2]:     return _hf_hub_download_to_cache_dir(
[rank2]:            ^^^^^^^^^^^^^^^^^^^^^^^^^^^^^^
[rank2]:   File "/home/winnieyangwn/miniconda3/envs/refat/lib/python3.11/site-packages/huggingface_hub/file_download.py", line 969, in _hf_hub_download_to_cache_dir
[rank2]:     _raise_on_head_call_error(head_call_error, force_download, local_files_only)
[rank2]:   File "/home/winnieyangwn/miniconda3/envs/refat/lib/python3.11/site-packages/huggingface_hub/file_download.py", line 1486, in _raise_on_head_call_error
[rank2]:     raise head_call_error
[rank2]:   File "/home/winnieyangwn/miniconda3/envs/refat/lib/python3.11/site-packages/huggingface_hub/file_download.py", line 1376, in _get_metadata_or_catch_error
[rank2]:     metadata = get_hf_file_metadata(
[rank2]:                ^^^^^^^^^^^^^^^^^^^^^
[rank2]:   File "/home/winnieyangwn/miniconda3/envs/refat/lib/python3.11/site-packages/huggingface_hub/utils/_validators.py", line 114, in _inner_fn
[rank2]:     return fn(*args, **kwargs)
[rank2]:            ^^^^^^^^^^^^^^^^^^^
[rank2]:   File "/home/winnieyangwn/miniconda3/envs/refat/lib/python3.11/site-packages/huggingface_hub/file_download.py", line 1296, in get_hf_file_metadata
[rank2]:     r = _request_wrapper(
[rank2]:         ^^^^^^^^^^^^^^^^^
[rank2]:   File "/home/winnieyangwn/miniconda3/envs/refat/lib/python3.11/site-packages/huggingface_hub/file_download.py", line 280, in _request_wrapper
[rank2]:     response = _request_wrapper(
[rank2]:                ^^^^^^^^^^^^^^^^^
[rank2]:   File "/home/winnieyangwn/miniconda3/envs/refat/lib/python3.11/site-packages/huggingface_hub/file_download.py", line 304, in _request_wrapper
[rank2]:     hf_raise_for_status(response)
[rank2]:   File "/home/winnieyangwn/miniconda3/envs/refat/lib/python3.11/site-packages/huggingface_hub/utils/_http.py", line 458, in hf_raise_for_status
[rank2]:     raise _format(RepositoryNotFoundError, message, response) from e
[rank2]: huggingface_hub.errors.RepositoryNotFoundError: 404 Client Error. (Request ID: Root=1-67e527d0-785a1bd444efd73d7d74e6f5;80356869-a84d-489c-94b2-074529ace8ed)

[rank2]: Repository Not Found for url: https://huggingface.co/meta-llama/Llama-3.1-70B-Instuct/resolve/main/config.json.
[rank2]: Please make sure you specified the correct `repo_id` and `repo_type`.
[rank2]: If you are trying to access a private or gated repo, make sure you are authenticated.

[rank2]: The above exception was the direct cause of the following exception:

[rank2]: Traceback (most recent call last):
[rank2]:   File "/opt/hpcaas/.mounts/fs-0301404b74c8d22fd/home/winnieyangwn/deception_and_jailbreak/src/submodules/truthfulQA/run_truthfulqa.py", line 122, in <module>
[rank2]:     main(model_path=args.model_path, 
[rank2]:     ^^^^^^^^^^^^^^^^^^^^^^^^^^^^^^^^
[rank2]:   File "/opt/hpcaas/.mounts/fs-0301404b74c8d22fd/home/winnieyangwn/deception_and_jailbreak/src/submodules/truthfulQA/run_truthfulqa.py", line 113, in main
[rank2]:     model_base = TransformerModelLoader(model_path, accelerator=accelerator)
[rank2]:                  ^^^^^^^^^^^^^^^^^^^^^^^^^^^^^^^^^^^^^^^^^^^^^^^^^^^^^^^^^^^
[rank2]:   File "/opt/hpcaas/.mounts/fs-0301404b74c8d22fd/home/winnieyangwn/deception_and_jailbreak/src/submodules/truthfulQA/model_base.py", line 41, in __init__
[rank2]:     self.model = AutoModelForCausalLM.from_pretrained(
[rank2]:                  ^^^^^^^^^^^^^^^^^^^^^^^^^^^^^^^^^^^^^
[rank2]:   File "/home/winnieyangwn/miniconda3/envs/refat/lib/python3.11/site-packages/transformers/models/auto/auto_factory.py", line 487, in from_pretrained
[rank2]:     resolved_config_file = cached_file(
[rank2]:                            ^^^^^^^^^^^^
[rank2]:   File "/home/winnieyangwn/miniconda3/envs/refat/lib/python3.11/site-packages/transformers/utils/hub.py", line 365, in cached_file
[rank2]:     raise EnvironmentError(
[rank2]: OSError: meta-llama/Llama-3.1-70B-Instuct is not a local folder and is not a valid model identifier listed on 'https://huggingface.co/models'
[rank2]: If this is a private repository, make sure to pass a token having permission to this repo either by logging in with `huggingface-cli login` or by passing `token=<your_token>`
[rank0]: Traceback (most recent call last):
[rank0]:   File "/home/winnieyangwn/miniconda3/envs/refat/lib/python3.11/site-packages/huggingface_hub/utils/_http.py", line 409, in hf_raise_for_status
[rank0]:     response.raise_for_status()
[rank0]:   File "/home/winnieyangwn/miniconda3/envs/refat/lib/python3.11/site-packages/requests/models.py", line 1024, in raise_for_status
[rank0]:     raise HTTPError(http_error_msg, response=self)
[rank0]: requests.exceptions.HTTPError: 404 Client Error: Not Found for url: https://huggingface.co/meta-llama/Llama-3.1-70B-Instuct/resolve/main/config.json

[rank0]: The above exception was the direct cause of the following exception:

[rank0]: Traceback (most recent call last):
[rank0]:   File "/home/winnieyangwn/miniconda3/envs/refat/lib/python3.11/site-packages/transformers/utils/hub.py", line 342, in cached_file
[rank0]:     resolved_file = hf_hub_download(
[rank0]:                     ^^^^^^^^^^^^^^^^
[rank0]:   File "/home/winnieyangwn/miniconda3/envs/refat/lib/python3.11/site-packages/huggingface_hub/utils/_validators.py", line 114, in _inner_fn
[rank0]:     return fn(*args, **kwargs)
[rank0]:            ^^^^^^^^^^^^^^^^^^^
[rank0]:   File "/home/winnieyangwn/miniconda3/envs/refat/lib/python3.11/site-packages/huggingface_hub/file_download.py", line 862, in hf_hub_download
[rank0]:     return _hf_hub_download_to_cache_dir(
[rank0]:            ^^^^^^^^^^^^^^^^^^^^^^^^^^^^^^
[rank0]:   File "/home/winnieyangwn/miniconda3/envs/refat/lib/python3.11/site-packages/huggingface_hub/file_download.py", line 969, in _hf_hub_download_to_cache_dir
[rank0]:     _raise_on_head_call_error(head_call_error, force_download, local_files_only)
[rank0]:   File "/home/winnieyangwn/miniconda3/envs/refat/lib/python3.11/site-packages/huggingface_hub/file_download.py", line 1486, in _raise_on_head_call_error
[rank0]:     raise head_call_error
[rank0]:   File "/home/winnieyangwn/miniconda3/envs/refat/lib/python3.11/site-packages/huggingface_hub/file_download.py", line 1376, in _get_metadata_or_catch_error
[rank0]:     metadata = get_hf_file_metadata(
[rank0]:                ^^^^^^^^^^^^^^^^^^^^^
[rank0]:   File "/home/winnieyangwn/miniconda3/envs/refat/lib/python3.11/site-packages/huggingface_hub/utils/_validators.py", line 114, in _inner_fn
[rank0]:     return fn(*args, **kwargs)
[rank0]:            ^^^^^^^^^^^^^^^^^^^
[rank0]:   File "/home/winnieyangwn/miniconda3/envs/refat/lib/python3.11/site-packages/huggingface_hub/file_download.py", line 1296, in get_hf_file_metadata
[rank0]:     r = _request_wrapper(
[rank0]:         ^^^^^^^^^^^^^^^^^
[rank0]:   File "/home/winnieyangwn/miniconda3/envs/refat/lib/python3.11/site-packages/huggingface_hub/file_download.py", line 280, in _request_wrapper
[rank0]:     response = _request_wrapper(
[rank0]:                ^^^^^^^^^^^^^^^^^
[rank0]:   File "/home/winnieyangwn/miniconda3/envs/refat/lib/python3.11/site-packages/huggingface_hub/file_download.py", line 304, in _request_wrapper
[rank0]:     hf_raise_for_status(response)
[rank0]:   File "/home/winnieyangwn/miniconda3/envs/refat/lib/python3.11/site-packages/huggingface_hub/utils/_http.py", line 458, in hf_raise_for_status
[rank0]:     raise _format(RepositoryNotFoundError, message, response) from e
[rank0]: huggingface_hub.errors.RepositoryNotFoundError: 404 Client Error. (Request ID: Root=1-67e527cf-1b7586732da61fc56d949331;58496c04-a784-4843-b6f7-3eaefcf2711d)

[rank0]: Repository Not Found for url: https://huggingface.co/meta-llama/Llama-3.1-70B-Instuct/resolve/main/config.json.
[rank0]: Please make sure you specified the correct `repo_id` and `repo_type`.
[rank0]: If you are trying to access a private or gated repo, make sure you are authenticated.

[rank0]: The above exception was the direct cause of the following exception:

[rank0]: Traceback (most recent call last):
[rank0]:   File "/opt/hpcaas/.mounts/fs-0301404b74c8d22fd/home/winnieyangwn/deception_and_jailbreak/src/submodules/truthfulQA/run_truthfulqa.py", line 122, in <module>
[rank0]:     main(model_path=args.model_path, 
[rank0]:     ^^^^^^^^^^^^^^^^^^^^^^^^^^^^^^^^
[rank0]:   File "/opt/hpcaas/.mounts/fs-0301404b74c8d22fd/home/winnieyangwn/deception_and_jailbreak/src/submodules/truthfulQA/run_truthfulqa.py", line 113, in main
[rank0]:     model_base = TransformerModelLoader(model_path, accelerator=accelerator)
[rank0]:                  ^^^^^^^^^^^^^^^^^^^^^^^^^^^^^^^^^^^^^^^^^^^^^^^^^^^^^^^^^^^
[rank0]:   File "/opt/hpcaas/.mounts/fs-0301404b74c8d22fd/home/winnieyangwn/deception_and_jailbreak/src/submodules/truthfulQA/model_base.py", line 41, in __init__
[rank0]:     self.model = AutoModelForCausalLM.from_pretrained(
[rank0]:                  ^^^^^^^^^^^^^^^^^^^^^^^^^^^^^^^^^^^^^
[rank0]:   File "/home/winnieyangwn/miniconda3/envs/refat/lib/python3.11/site-packages/transformers/models/auto/auto_factory.py", line 487, in from_pretrained
[rank0]:     resolved_config_file = cached_file(
[rank0]:                            ^^^^^^^^^^^^
[rank0]:   File "/home/winnieyangwn/miniconda3/envs/refat/lib/python3.11/site-packages/transformers/utils/hub.py", line 365, in cached_file
[rank0]:     raise EnvironmentError(
[rank0]: OSError: meta-llama/Llama-3.1-70B-Instuct is not a local folder and is not a valid model identifier listed on 'https://huggingface.co/models'
[rank0]: If this is a private repository, make sure to pass a token having permission to this repo either by logging in with `huggingface-cli login` or by passing `token=<your_token>`
[rank0]:[W327 10:26:26.805854612 ProcessGroupNCCL.cpp:1250] Warning: WARNING: process group has NOT been destroyed before we destruct ProcessGroupNCCL. On normal program exit, the application should call destroy_process_group to ensure that any pending NCCL operations have finished in this process. In rare cases this process can exit before this point and block the progress of another member of the process group. This constraint has always been present,  but this warning has only been added since PyTorch 2.4 (function operator())
W0327 10:26:30.076000 1399947 /opt/hpcaas/.mounts/fs-0301404b74c8d22fd/home/winnieyangwn/miniconda3/envs/refat/lib/python3.11/site-packages/torch/distributed/elastic/multiprocessing/api.py:897] Sending process 1400752 closing signal SIGTERM
W0327 10:26:30.078000 1399947 /opt/hpcaas/.mounts/fs-0301404b74c8d22fd/home/winnieyangwn/miniconda3/envs/refat/lib/python3.11/site-packages/torch/distributed/elastic/multiprocessing/api.py:897] Sending process 1400753 closing signal SIGTERM
W0327 10:26:30.079000 1399947 /opt/hpcaas/.mounts/fs-0301404b74c8d22fd/home/winnieyangwn/miniconda3/envs/refat/lib/python3.11/site-packages/torch/distributed/elastic/multiprocessing/api.py:897] Sending process 1400754 closing signal SIGTERM
W0327 10:26:30.082000 1399947 /opt/hpcaas/.mounts/fs-0301404b74c8d22fd/home/winnieyangwn/miniconda3/envs/refat/lib/python3.11/site-packages/torch/distributed/elastic/multiprocessing/api.py:897] Sending process 1400756 closing signal SIGTERM
W0327 10:26:30.082000 1399947 /opt/hpcaas/.mounts/fs-0301404b74c8d22fd/home/winnieyangwn/miniconda3/envs/refat/lib/python3.11/site-packages/torch/distributed/elastic/multiprocessing/api.py:897] Sending process 1400757 closing signal SIGTERM
E0327 10:26:31.506000 1399947 /opt/hpcaas/.mounts/fs-0301404b74c8d22fd/home/winnieyangwn/miniconda3/envs/refat/lib/python3.11/site-packages/torch/distributed/elastic/multiprocessing/api.py:869] failed (exitcode: 1) local_rank: 0 (pid: 1400751) of binary: /home/winnieyangwn/miniconda3/envs/refat/bin/python3.11
Traceback (most recent call last):
  File "/home/winnieyangwn/miniconda3/envs/refat/bin/accelerate", line 8, in <module>
    sys.exit(main())
             ^^^^^^
  File "/home/winnieyangwn/miniconda3/envs/refat/lib/python3.11/site-packages/accelerate/commands/accelerate_cli.py", line 48, in main
    args.func(args)
  File "/home/winnieyangwn/miniconda3/envs/refat/lib/python3.11/site-packages/accelerate/commands/launch.py", line 1185, in launch_command
    multi_gpu_launcher(args)
  File "/home/winnieyangwn/miniconda3/envs/refat/lib/python3.11/site-packages/accelerate/commands/launch.py", line 810, in multi_gpu_launcher
    distrib_run.run(args)
  File "/home/winnieyangwn/miniconda3/envs/refat/lib/python3.11/site-packages/torch/distributed/run.py", line 910, in run
    elastic_launch(
  File "/home/winnieyangwn/miniconda3/envs/refat/lib/python3.11/site-packages/torch/distributed/launcher/api.py", line 138, in __call__
    return launch_agent(self._config, self._entrypoint, list(args))
           ^^^^^^^^^^^^^^^^^^^^^^^^^^^^^^^^^^^^^^^^^^^^^^^^^^^^^^^^
  File "/home/winnieyangwn/miniconda3/envs/refat/lib/python3.11/site-packages/torch/distributed/launcher/api.py", line 269, in launch_agent
    raise ChildFailedError(
torch.distributed.elastic.multiprocessing.errors.ChildFailedError: 
============================================================
run_truthfulqa.py FAILED
------------------------------------------------------------
Failures:
[1]:
  time      : 2025-03-27_10:26:30
  host      : cr6-p548xlarge-3.genai-h100.hpcaas
  rank      : 4 (local_rank: 4)
  exitcode  : 1 (pid: 1400755)
  error_file: <N/A>
  traceback : To enable traceback see: https://pytorch.org/docs/stable/elastic/errors.html
[2]:
  time      : 2025-03-27_10:26:30
  host      : cr6-p548xlarge-3.genai-h100.hpcaas
  rank      : 7 (local_rank: 7)
  exitcode  : 1 (pid: 1400758)
  error_file: <N/A>
  traceback : To enable traceback see: https://pytorch.org/docs/stable/elastic/errors.html
------------------------------------------------------------
Root Cause (first observed failure):
[0]:
  time      : 2025-03-27_10:26:30
  host      : cr6-p548xlarge-3.genai-h100.hpcaas
  rank      : 0 (local_rank: 0)
  exitcode  : 1 (pid: 1400751)
  error_file: <N/A>
  traceback : To enable traceback see: https://pytorch.org/docs/stable/elastic/errors.html
============================================================
srun: error: cr6-p548xlarge-3: task 0: Exited with exit code 1
srun: Terminating StepId=128835.0
